ERROR 2016-06-17 12:24:21,911 Internal Server Error: /user/logout/
Traceback (most recent call last):
  File "D:\python\python2.7.10\lib\site-packages\django\core\handlers\base.py", line 158, in get_response
    % (callback.__module__, view_name))
ValueError: The view user_management.views.wrapper didn't return an HttpResponse object. It returned None instead.
ERROR 2016-06-17 14:37:10,895 Internal Server Error: /api/user/
Traceback (most recent call last):
  File "D:\python\python2.7.10\lib\site-packages\django\core\handlers\base.py", line 149, in get_response
    response = self.process_exception_by_middleware(e, request)
  File "D:\python\python2.7.10\lib\site-packages\django\core\handlers\base.py", line 147, in get_response
    response = wrapped_callback(request, *callback_args, **callback_kwargs)
  File "D:\python\python2.7.10\lib\site-packages\django\views\decorators\csrf.py", line 58, in wrapped_view
    return view_func(*args, **kwargs)
  File "D:\python\python2.7.10\lib\site-packages\rest_framework\viewsets.py", line 87, in view
    return self.dispatch(request, *args, **kwargs)
  File "D:\python\python2.7.10\lib\site-packages\rest_framework\views.py", line 466, in dispatch
    response = self.handle_exception(exc)
  File "D:\python\python2.7.10\lib\site-packages\rest_framework\views.py", line 454, in dispatch
    self.initial(request, *args, **kwargs)
  File "D:\python\python2.7.10\lib\site-packages\rest_framework\views.py", line 376, in initial
    self.perform_authentication(request)
  File "D:\python\python2.7.10\lib\site-packages\rest_framework\views.py", line 310, in perform_authentication
    request.user
  File "D:\python\python2.7.10\lib\site-packages\rest_framework\request.py", line 353, in __getattribute__
    return super(Request, self).__getattribute__(attr)
  File "D:\python\python2.7.10\lib\site-packages\rest_framework\request.py", line 193, in user
    self._authenticate()
  File "D:\python\python2.7.10\lib\site-packages\rest_framework\request.py", line 316, in _authenticate
    user_auth_tuple = authenticator.authenticate(self)
  File "D:\python\python2.7.10\lib\site-packages\rest_framework\authentication.py", line 118, in authenticate
    if request.session('islogin'):
TypeError: 'SessionStore' object is not callable
ERROR 2016-06-17 14:37:28,803 Internal Server Error: /api/user/
Traceback (most recent call last):
  File "D:\python\python2.7.10\lib\site-packages\django\core\handlers\base.py", line 149, in get_response
    response = self.process_exception_by_middleware(e, request)
  File "D:\python\python2.7.10\lib\site-packages\django\core\handlers\base.py", line 147, in get_response
    response = wrapped_callback(request, *callback_args, **callback_kwargs)
  File "D:\python\python2.7.10\lib\site-packages\django\views\decorators\csrf.py", line 58, in wrapped_view
    return view_func(*args, **kwargs)
  File "D:\python\python2.7.10\lib\site-packages\rest_framework\viewsets.py", line 87, in view
    return self.dispatch(request, *args, **kwargs)
  File "D:\python\python2.7.10\lib\site-packages\rest_framework\views.py", line 466, in dispatch
    response = self.handle_exception(exc)
  File "D:\python\python2.7.10\lib\site-packages\rest_framework\views.py", line 454, in dispatch
    self.initial(request, *args, **kwargs)
  File "D:\python\python2.7.10\lib\site-packages\rest_framework\views.py", line 376, in initial
    self.perform_authentication(request)
  File "D:\python\python2.7.10\lib\site-packages\rest_framework\views.py", line 310, in perform_authentication
    request.user
  File "D:\python\python2.7.10\lib\site-packages\rest_framework\request.py", line 353, in __getattribute__
    return super(Request, self).__getattribute__(attr)
  File "D:\python\python2.7.10\lib\site-packages\rest_framework\request.py", line 193, in user
    self._authenticate()
  File "D:\python\python2.7.10\lib\site-packages\rest_framework\request.py", line 316, in _authenticate
    user_auth_tuple = authenticator.authenticate(self)
  File "D:\python\python2.7.10\lib\site-packages\rest_framework\authentication.py", line 118, in authenticate
    if request.session('islogin'):
TypeError: 'SessionStore' object is not callable
ERROR 2016-06-17 14:37:40,717 Internal Server Error: /api/
Traceback (most recent call last):
  File "D:\python\python2.7.10\lib\site-packages\django\core\handlers\base.py", line 149, in get_response
    response = self.process_exception_by_middleware(e, request)
  File "D:\python\python2.7.10\lib\site-packages\django\core\handlers\base.py", line 147, in get_response
    response = wrapped_callback(request, *callback_args, **callback_kwargs)
  File "D:\python\python2.7.10\lib\site-packages\django\views\decorators\csrf.py", line 58, in wrapped_view
    return view_func(*args, **kwargs)
  File "D:\python\python2.7.10\lib\site-packages\django\views\generic\base.py", line 68, in view
    return self.dispatch(request, *args, **kwargs)
  File "D:\python\python2.7.10\lib\site-packages\rest_framework\views.py", line 466, in dispatch
    response = self.handle_exception(exc)
  File "D:\python\python2.7.10\lib\site-packages\rest_framework\views.py", line 454, in dispatch
    self.initial(request, *args, **kwargs)
  File "D:\python\python2.7.10\lib\site-packages\rest_framework\views.py", line 376, in initial
    self.perform_authentication(request)
  File "D:\python\python2.7.10\lib\site-packages\rest_framework\views.py", line 310, in perform_authentication
    request.user
  File "D:\python\python2.7.10\lib\site-packages\rest_framework\request.py", line 353, in __getattribute__
    return super(Request, self).__getattribute__(attr)
  File "D:\python\python2.7.10\lib\site-packages\rest_framework\request.py", line 193, in user
    self._authenticate()
  File "D:\python\python2.7.10\lib\site-packages\rest_framework\request.py", line 316, in _authenticate
    user_auth_tuple = authenticator.authenticate(self)
  File "D:\python\python2.7.10\lib\site-packages\rest_framework\authentication.py", line 118, in authenticate
    if request.session('islogin'):
TypeError: 'SessionStore' object is not callable
ERROR 2016-06-17 16:31:11,551 Internal Server Error: /user/logout/
Traceback (most recent call last):
  File "D:\python\python2.7.10\lib\site-packages\django\core\handlers\base.py", line 158, in get_response
    % (callback.__module__, view_name))
ValueError: The view user_management.views.wrapper didn't return an HttpResponse object. It returned None instead.
ERROR 2016-06-17 17:52:35,321 Internal Server Error: /login/
Traceback (most recent call last):
  File "D:\python\python2.7.10\lib\site-packages\django\core\handlers\base.py", line 149, in get_response
    response = self.process_exception_by_middleware(e, request)
  File "D:\python\python2.7.10\lib\site-packages\django\core\handlers\base.py", line 147, in get_response
    response = wrapped_callback(request, *callback_args, **callback_kwargs)
  File "D:\python_dj\yunweiPT\user_management\views.py", line 122, in login
    return render('/assets/mgroom/1/',context_instance=RequestContext(request))
TypeError: render() takes at least 2 arguments (2 given)
ERROR 2016-06-17 17:52:48,894 Internal Server Error: /login/
Traceback (most recent call last):
  File "D:\python\python2.7.10\lib\site-packages\django\core\handlers\base.py", line 149, in get_response
    response = self.process_exception_by_middleware(e, request)
  File "D:\python\python2.7.10\lib\site-packages\django\core\handlers\base.py", line 147, in get_response
    response = wrapped_callback(request, *callback_args, **callback_kwargs)
  File "D:\python_dj\yunweiPT\user_management\views.py", line 122, in login
    return render('/assets/mgroom/1/',context_instance=RequestContext(request))
TypeError: render() takes at least 2 arguments (2 given)
ERROR 2016-06-17 17:53:56,036 Internal Server Error: /login/
Traceback (most recent call last):
  File "D:\python\python2.7.10\lib\site-packages\django\core\handlers\base.py", line 149, in get_response
    response = self.process_exception_by_middleware(e, request)
  File "D:\python\python2.7.10\lib\site-packages\django\core\handlers\base.py", line 147, in get_response
    response = wrapped_callback(request, *callback_args, **callback_kwargs)
  File "D:\python_dj\yunweiPT\user_management\views.py", line 122, in login
    return render('/assets/mgroom/1/',context_instance=RequestContext(request))
TypeError: render() takes at least 2 arguments (2 given)
ERROR 2016-06-17 17:54:04,696 Internal Server Error: /login/
Traceback (most recent call last):
  File "D:\python\python2.7.10\lib\site-packages\django\core\handlers\base.py", line 149, in get_response
    response = self.process_exception_by_middleware(e, request)
  File "D:\python\python2.7.10\lib\site-packages\django\core\handlers\base.py", line 147, in get_response
    response = wrapped_callback(request, *callback_args, **callback_kwargs)
  File "D:\python_dj\yunweiPT\user_management\views.py", line 122, in login
    return render('/assets/mgroom/1/',context_instance=RequestContext(request))
TypeError: render() takes at least 2 arguments (2 given)
ERROR 2016-06-17 18:01:01,288 Internal Server Error: /options/install/
Traceback (most recent call last):
  File "D:\python\python2.7.10\lib\site-packages\django\core\handlers\base.py", line 149, in get_response
    response = self.process_exception_by_middleware(e, request)
  File "D:\python\python2.7.10\lib\site-packages\django\core\handlers\base.py", line 147, in get_response
    response = wrapped_callback(request, *callback_args, **callback_kwargs)
  File "D:\python_dj\yunweiPT\options\views.py", line 18, in wrapper
    return func(request,*args,**kwargs)
  File "D:\python_dj\yunweiPT\options\views.py", line 43, in install_server
    return render_to_response('install.html',info,context_instance=RequestContext(request))
NameError: global name 'RequestContext' is not defined
ERROR 2016-06-17 18:01:03,344 Internal Server Error: /options/install/
Traceback (most recent call last):
  File "D:\python\python2.7.10\lib\site-packages\django\core\handlers\base.py", line 149, in get_response
    response = self.process_exception_by_middleware(e, request)
  File "D:\python\python2.7.10\lib\site-packages\django\core\handlers\base.py", line 147, in get_response
    response = wrapped_callback(request, *callback_args, **callback_kwargs)
  File "D:\python_dj\yunweiPT\options\views.py", line 18, in wrapper
    return func(request,*args,**kwargs)
  File "D:\python_dj\yunweiPT\options\views.py", line 43, in install_server
    return render_to_response('install.html',info,context_instance=RequestContext(request))
NameError: global name 'RequestContext' is not defined
ERROR 2016-06-17 18:01:06,881 Internal Server Error: /options/install/
Traceback (most recent call last):
  File "D:\python\python2.7.10\lib\site-packages\django\core\handlers\base.py", line 149, in get_response
    response = self.process_exception_by_middleware(e, request)
  File "D:\python\python2.7.10\lib\site-packages\django\core\handlers\base.py", line 147, in get_response
    response = wrapped_callback(request, *callback_args, **callback_kwargs)
  File "D:\python_dj\yunweiPT\options\views.py", line 18, in wrapper
    return func(request,*args,**kwargs)
  File "D:\python_dj\yunweiPT\options\views.py", line 43, in install_server
    return render_to_response('install.html',info,context_instance=RequestContext(request))
NameError: global name 'RequestContext' is not defined
ERROR 2016-06-17 18:01:12,503 Internal Server Error: /options/close/
Traceback (most recent call last):
  File "D:\python\python2.7.10\lib\site-packages\django\core\handlers\base.py", line 149, in get_response
    response = self.process_exception_by_middleware(e, request)
  File "D:\python\python2.7.10\lib\site-packages\django\core\handlers\base.py", line 147, in get_response
    response = wrapped_callback(request, *callback_args, **callback_kwargs)
  File "D:\python_dj\yunweiPT\options\views.py", line 18, in wrapper
    return func(request,*args,**kwargs)
  File "D:\python_dj\yunweiPT\options\views.py", line 88, in close_server
    return render_to_response('close.html',info,context_instance=RequestContext(request))
NameError: global name 'RequestContext' is not defined
ERROR 2016-06-17 18:16:18,714 Internal Server Error: /options/remoteoptions/
Traceback (most recent call last):
  File "D:\python\python2.7.10\lib\site-packages\django\core\handlers\base.py", line 149, in get_response
    response = self.process_exception_by_middleware(e, request)
  File "D:\python\python2.7.10\lib\site-packages\django\core\handlers\base.py", line 147, in get_response
    response = wrapped_callback(request, *callback_args, **callback_kwargs)
  File "D:\python_dj\yunweiPT\options\views.py", line 19, in wrapper
    return func(request,*args,**kwargs)
  File "D:\python_dj\yunweiPT\options\views.py", line 102, in remoteoptions
    return HttpResponse('OK',context_instance=RequestContext(request))
  File "D:\python\python2.7.10\lib\site-packages\django\http\response.py", line 283, in __init__
    super(HttpResponse, self).__init__(*args, **kwargs)
TypeError: __init__() got an unexpected keyword argument 'context_instance'
ERROR 2016-06-17 18:16:20,740 Internal Server Error: /options/readoutput/
Traceback (most recent call last):
  File "D:\python\python2.7.10\lib\site-packages\django\core\handlers\base.py", line 149, in get_response
    response = self.process_exception_by_middleware(e, request)
  File "D:\python\python2.7.10\lib\site-packages\django\core\handlers\base.py", line 147, in get_response
    response = wrapped_callback(request, *callback_args, **callback_kwargs)
  File "D:\python_dj\yunweiPT\options\views.py", line 19, in wrapper
    return func(request,*args,**kwargs)
  File "D:\python_dj\yunweiPT\options\views.py", line 137, in readoutput
    return HttpResponse(datainfo,context_instance=RequestContext(request))
  File "D:\python\python2.7.10\lib\site-packages\django\http\response.py", line 283, in __init__
    super(HttpResponse, self).__init__(*args, **kwargs)
TypeError: __init__() got an unexpected keyword argument 'context_instance'
ERROR 2016-06-17 18:16:22,734 Internal Server Error: /options/readoutput/
Traceback (most recent call last):
  File "D:\python\python2.7.10\lib\site-packages\django\core\handlers\base.py", line 149, in get_response
    response = self.process_exception_by_middleware(e, request)
  File "D:\python\python2.7.10\lib\site-packages\django\core\handlers\base.py", line 147, in get_response
    response = wrapped_callback(request, *callback_args, **callback_kwargs)
  File "D:\python_dj\yunweiPT\options\views.py", line 19, in wrapper
    return func(request,*args,**kwargs)
  File "D:\python_dj\yunweiPT\options\views.py", line 137, in readoutput
    return HttpResponse(datainfo,context_instance=RequestContext(request))
  File "D:\python\python2.7.10\lib\site-packages\django\http\response.py", line 283, in __init__
    super(HttpResponse, self).__init__(*args, **kwargs)
TypeError: __init__() got an unexpected keyword argument 'context_instance'
ERROR 2016-06-17 18:16:24,744 Internal Server Error: /options/readoutput/
Traceback (most recent call last):
  File "D:\python\python2.7.10\lib\site-packages\django\core\handlers\base.py", line 149, in get_response
    response = self.process_exception_by_middleware(e, request)
  File "D:\python\python2.7.10\lib\site-packages\django\core\handlers\base.py", line 147, in get_response
    response = wrapped_callback(request, *callback_args, **callback_kwargs)
  File "D:\python_dj\yunweiPT\options\views.py", line 19, in wrapper
    return func(request,*args,**kwargs)
  File "D:\python_dj\yunweiPT\options\views.py", line 137, in readoutput
    return HttpResponse(datainfo,context_instance=RequestContext(request))
  File "D:\python\python2.7.10\lib\site-packages\django\http\response.py", line 283, in __init__
    super(HttpResponse, self).__init__(*args, **kwargs)
TypeError: __init__() got an unexpected keyword argument 'context_instance'
ERROR 2016-06-17 18:16:26,714 Internal Server Error: /options/readoutput/
Traceback (most recent call last):
  File "D:\python\python2.7.10\lib\site-packages\django\core\handlers\base.py", line 149, in get_response
    response = self.process_exception_by_middleware(e, request)
  File "D:\python\python2.7.10\lib\site-packages\django\core\handlers\base.py", line 147, in get_response
    response = wrapped_callback(request, *callback_args, **callback_kwargs)
  File "D:\python_dj\yunweiPT\options\views.py", line 19, in wrapper
    return func(request,*args,**kwargs)
  File "D:\python_dj\yunweiPT\options\views.py", line 137, in readoutput
    return HttpResponse(datainfo,context_instance=RequestContext(request))
  File "D:\python\python2.7.10\lib\site-packages\django\http\response.py", line 283, in __init__
    super(HttpResponse, self).__init__(*args, **kwargs)
TypeError: __init__() got an unexpected keyword argument 'context_instance'
ERROR 2016-06-17 18:16:28,734 Internal Server Error: /options/readoutput/
Traceback (most recent call last):
  File "D:\python\python2.7.10\lib\site-packages\django\core\handlers\base.py", line 149, in get_response
    response = self.process_exception_by_middleware(e, request)
  File "D:\python\python2.7.10\lib\site-packages\django\core\handlers\base.py", line 147, in get_response
    response = wrapped_callback(request, *callback_args, **callback_kwargs)
  File "D:\python_dj\yunweiPT\options\views.py", line 19, in wrapper
    return func(request,*args,**kwargs)
  File "D:\python_dj\yunweiPT\options\views.py", line 137, in readoutput
    return HttpResponse(datainfo,context_instance=RequestContext(request))
  File "D:\python\python2.7.10\lib\site-packages\django\http\response.py", line 283, in __init__
    super(HttpResponse, self).__init__(*args, **kwargs)
TypeError: __init__() got an unexpected keyword argument 'context_instance'
ERROR 2016-06-17 18:16:30,737 Internal Server Error: /options/readoutput/
Traceback (most recent call last):
  File "D:\python\python2.7.10\lib\site-packages\django\core\handlers\base.py", line 149, in get_response
    response = self.process_exception_by_middleware(e, request)
  File "D:\python\python2.7.10\lib\site-packages\django\core\handlers\base.py", line 147, in get_response
    response = wrapped_callback(request, *callback_args, **callback_kwargs)
  File "D:\python_dj\yunweiPT\options\views.py", line 19, in wrapper
    return func(request,*args,**kwargs)
  File "D:\python_dj\yunweiPT\options\views.py", line 137, in readoutput
    return HttpResponse(datainfo,context_instance=RequestContext(request))
  File "D:\python\python2.7.10\lib\site-packages\django\http\response.py", line 283, in __init__
    super(HttpResponse, self).__init__(*args, **kwargs)
TypeError: __init__() got an unexpected keyword argument 'context_instance'
ERROR 2016-06-17 18:16:32,737 Internal Server Error: /options/readoutput/
Traceback (most recent call last):
  File "D:\python\python2.7.10\lib\site-packages\django\core\handlers\base.py", line 149, in get_response
    response = self.process_exception_by_middleware(e, request)
  File "D:\python\python2.7.10\lib\site-packages\django\core\handlers\base.py", line 147, in get_response
    response = wrapped_callback(request, *callback_args, **callback_kwargs)
  File "D:\python_dj\yunweiPT\options\views.py", line 19, in wrapper
    return func(request,*args,**kwargs)
  File "D:\python_dj\yunweiPT\options\views.py", line 137, in readoutput
    return HttpResponse(datainfo,context_instance=RequestContext(request))
  File "D:\python\python2.7.10\lib\site-packages\django\http\response.py", line 283, in __init__
    super(HttpResponse, self).__init__(*args, **kwargs)
TypeError: __init__() got an unexpected keyword argument 'context_instance'
ERROR 2016-06-17 18:18:33,717 Internal Server Error: /options/remoteoptions/
Traceback (most recent call last):
  File "D:\python\python2.7.10\lib\site-packages\django\core\handlers\base.py", line 149, in get_response
    response = self.process_exception_by_middleware(e, request)
  File "D:\python\python2.7.10\lib\site-packages\django\core\handlers\base.py", line 147, in get_response
    response = wrapped_callback(request, *callback_args, **callback_kwargs)
  File "D:\python_dj\yunweiPT\options\views.py", line 19, in wrapper
    return func(request,*args,**kwargs)
  File "D:\python_dj\yunweiPT\options\views.py", line 102, in remoteoptions
    return HttpResponse('OK',context_instance=RequestContext(request))
  File "D:\python\python2.7.10\lib\site-packages\django\http\response.py", line 283, in __init__
    super(HttpResponse, self).__init__(*args, **kwargs)
TypeError: __init__() got an unexpected keyword argument 'context_instance'
ERROR 2016-06-17 18:18:35,733 Internal Server Error: /options/readoutput/
Traceback (most recent call last):
  File "D:\python\python2.7.10\lib\site-packages\django\core\handlers\base.py", line 149, in get_response
    response = self.process_exception_by_middleware(e, request)
  File "D:\python\python2.7.10\lib\site-packages\django\core\handlers\base.py", line 147, in get_response
    response = wrapped_callback(request, *callback_args, **callback_kwargs)
  File "D:\python_dj\yunweiPT\options\views.py", line 19, in wrapper
    return func(request,*args,**kwargs)
  File "D:\python_dj\yunweiPT\options\views.py", line 137, in readoutput
    return HttpResponse(datainfo,context_instance=RequestContext(request))
  File "D:\python\python2.7.10\lib\site-packages\django\http\response.py", line 283, in __init__
    super(HttpResponse, self).__init__(*args, **kwargs)
TypeError: __init__() got an unexpected keyword argument 'context_instance'
ERROR 2016-06-17 18:18:37,730 Internal Server Error: /options/readoutput/
Traceback (most recent call last):
  File "D:\python\python2.7.10\lib\site-packages\django\core\handlers\base.py", line 149, in get_response
    response = self.process_exception_by_middleware(e, request)
  File "D:\python\python2.7.10\lib\site-packages\django\core\handlers\base.py", line 147, in get_response
    response = wrapped_callback(request, *callback_args, **callback_kwargs)
  File "D:\python_dj\yunweiPT\options\views.py", line 19, in wrapper
    return func(request,*args,**kwargs)
  File "D:\python_dj\yunweiPT\options\views.py", line 137, in readoutput
    return HttpResponse(datainfo,context_instance=RequestContext(request))
  File "D:\python\python2.7.10\lib\site-packages\django\http\response.py", line 283, in __init__
    super(HttpResponse, self).__init__(*args, **kwargs)
TypeError: __init__() got an unexpected keyword argument 'context_instance'
ERROR 2016-06-17 18:18:39,733 Internal Server Error: /options/readoutput/
Traceback (most recent call last):
  File "D:\python\python2.7.10\lib\site-packages\django\core\handlers\base.py", line 149, in get_response
    response = self.process_exception_by_middleware(e, request)
  File "D:\python\python2.7.10\lib\site-packages\django\core\handlers\base.py", line 147, in get_response
    response = wrapped_callback(request, *callback_args, **callback_kwargs)
  File "D:\python_dj\yunweiPT\options\views.py", line 19, in wrapper
    return func(request,*args,**kwargs)
  File "D:\python_dj\yunweiPT\options\views.py", line 137, in readoutput
    return HttpResponse(datainfo,context_instance=RequestContext(request))
  File "D:\python\python2.7.10\lib\site-packages\django\http\response.py", line 283, in __init__
    super(HttpResponse, self).__init__(*args, **kwargs)
TypeError: __init__() got an unexpected keyword argument 'context_instance'
ERROR 2016-06-17 18:18:41,713 Internal Server Error: /options/readoutput/
Traceback (most recent call last):
  File "D:\python\python2.7.10\lib\site-packages\django\core\handlers\base.py", line 149, in get_response
    response = self.process_exception_by_middleware(e, request)
  File "D:\python\python2.7.10\lib\site-packages\django\core\handlers\base.py", line 147, in get_response
    response = wrapped_callback(request, *callback_args, **callback_kwargs)
  File "D:\python_dj\yunweiPT\options\views.py", line 19, in wrapper
    return func(request,*args,**kwargs)
  File "D:\python_dj\yunweiPT\options\views.py", line 137, in readoutput
    return HttpResponse(datainfo,context_instance=RequestContext(request))
  File "D:\python\python2.7.10\lib\site-packages\django\http\response.py", line 283, in __init__
    super(HttpResponse, self).__init__(*args, **kwargs)
TypeError: __init__() got an unexpected keyword argument 'context_instance'
ERROR 2016-06-17 18:18:43,732 Internal Server Error: /options/readoutput/
Traceback (most recent call last):
  File "D:\python\python2.7.10\lib\site-packages\django\core\handlers\base.py", line 149, in get_response
    response = self.process_exception_by_middleware(e, request)
  File "D:\python\python2.7.10\lib\site-packages\django\core\handlers\base.py", line 147, in get_response
    response = wrapped_callback(request, *callback_args, **callback_kwargs)
  File "D:\python_dj\yunweiPT\options\views.py", line 19, in wrapper
    return func(request,*args,**kwargs)
  File "D:\python_dj\yunweiPT\options\views.py", line 137, in readoutput
    return HttpResponse(datainfo,context_instance=RequestContext(request))
  File "D:\python\python2.7.10\lib\site-packages\django\http\response.py", line 283, in __init__
    super(HttpResponse, self).__init__(*args, **kwargs)
TypeError: __init__() got an unexpected keyword argument 'context_instance'
ERROR 2016-06-17 18:18:45,713 Internal Server Error: /options/readoutput/
Traceback (most recent call last):
  File "D:\python\python2.7.10\lib\site-packages\django\core\handlers\base.py", line 149, in get_response
    response = self.process_exception_by_middleware(e, request)
  File "D:\python\python2.7.10\lib\site-packages\django\core\handlers\base.py", line 147, in get_response
    response = wrapped_callback(request, *callback_args, **callback_kwargs)
  File "D:\python_dj\yunweiPT\options\views.py", line 19, in wrapper
    return func(request,*args,**kwargs)
  File "D:\python_dj\yunweiPT\options\views.py", line 137, in readoutput
    return HttpResponse(datainfo,context_instance=RequestContext(request))
  File "D:\python\python2.7.10\lib\site-packages\django\http\response.py", line 283, in __init__
    super(HttpResponse, self).__init__(*args, **kwargs)
TypeError: __init__() got an unexpected keyword argument 'context_instance'
ERROR 2016-06-17 18:22:02,678 Internal Server Error: /options/remoteoptions/
Traceback (most recent call last):
  File "D:\python\python2.7.10\lib\site-packages\django\core\handlers\base.py", line 149, in get_response
    response = self.process_exception_by_middleware(e, request)
  File "D:\python\python2.7.10\lib\site-packages\django\core\handlers\base.py", line 147, in get_response
    response = wrapped_callback(request, *callback_args, **callback_kwargs)
  File "D:\python_dj\yunweiPT\options\views.py", line 19, in wrapper
    return func(request,*args,**kwargs)
  File "D:\python_dj\yunweiPT\options\views.py", line 102, in remoteoptions
    return HttpResponse('OK',context_instance=RequestContext(request))
  File "D:\python\python2.7.10\lib\site-packages\django\http\response.py", line 283, in __init__
    super(HttpResponse, self).__init__(*args, **kwargs)
TypeError: __init__() got an unexpected keyword argument 'context_instance'
ERROR 2016-06-17 18:22:04,759 Internal Server Error: /options/readoutput/
Traceback (most recent call last):
  File "D:\python\python2.7.10\lib\site-packages\django\core\handlers\base.py", line 149, in get_response
    response = self.process_exception_by_middleware(e, request)
  File "D:\python\python2.7.10\lib\site-packages\django\core\handlers\base.py", line 147, in get_response
    response = wrapped_callback(request, *callback_args, **callback_kwargs)
  File "D:\python_dj\yunweiPT\options\views.py", line 19, in wrapper
    return func(request,*args,**kwargs)
  File "D:\python_dj\yunweiPT\options\views.py", line 137, in readoutput
    return HttpResponse(datainfo,context_instance=RequestContext(request))
  File "D:\python\python2.7.10\lib\site-packages\django\http\response.py", line 283, in __init__
    super(HttpResponse, self).__init__(*args, **kwargs)
TypeError: __init__() got an unexpected keyword argument 'context_instance'
ERROR 2016-06-17 18:22:06,752 Internal Server Error: /options/readoutput/
Traceback (most recent call last):
  File "D:\python\python2.7.10\lib\site-packages\django\core\handlers\base.py", line 149, in get_response
    response = self.process_exception_by_middleware(e, request)
  File "D:\python\python2.7.10\lib\site-packages\django\core\handlers\base.py", line 147, in get_response
    response = wrapped_callback(request, *callback_args, **callback_kwargs)
  File "D:\python_dj\yunweiPT\options\views.py", line 19, in wrapper
    return func(request,*args,**kwargs)
  File "D:\python_dj\yunweiPT\options\views.py", line 137, in readoutput
    return HttpResponse(datainfo,context_instance=RequestContext(request))
  File "D:\python\python2.7.10\lib\site-packages\django\http\response.py", line 283, in __init__
    super(HttpResponse, self).__init__(*args, **kwargs)
TypeError: __init__() got an unexpected keyword argument 'context_instance'
ERROR 2016-06-17 18:22:08,736 Internal Server Error: /options/readoutput/
Traceback (most recent call last):
  File "D:\python\python2.7.10\lib\site-packages\django\core\handlers\base.py", line 149, in get_response
    response = self.process_exception_by_middleware(e, request)
  File "D:\python\python2.7.10\lib\site-packages\django\core\handlers\base.py", line 147, in get_response
    response = wrapped_callback(request, *callback_args, **callback_kwargs)
  File "D:\python_dj\yunweiPT\options\views.py", line 19, in wrapper
    return func(request,*args,**kwargs)
  File "D:\python_dj\yunweiPT\options\views.py", line 137, in readoutput
    return HttpResponse(datainfo,context_instance=RequestContext(request))
  File "D:\python\python2.7.10\lib\site-packages\django\http\response.py", line 283, in __init__
    super(HttpResponse, self).__init__(*args, **kwargs)
TypeError: __init__() got an unexpected keyword argument 'context_instance'
ERROR 2016-06-17 18:22:10,759 Internal Server Error: /options/readoutput/
Traceback (most recent call last):
  File "D:\python\python2.7.10\lib\site-packages\django\core\handlers\base.py", line 149, in get_response
    response = self.process_exception_by_middleware(e, request)
  File "D:\python\python2.7.10\lib\site-packages\django\core\handlers\base.py", line 147, in get_response
    response = wrapped_callback(request, *callback_args, **callback_kwargs)
  File "D:\python_dj\yunweiPT\options\views.py", line 19, in wrapper
    return func(request,*args,**kwargs)
  File "D:\python_dj\yunweiPT\options\views.py", line 137, in readoutput
    return HttpResponse(datainfo,context_instance=RequestContext(request))
  File "D:\python\python2.7.10\lib\site-packages\django\http\response.py", line 283, in __init__
    super(HttpResponse, self).__init__(*args, **kwargs)
TypeError: __init__() got an unexpected keyword argument 'context_instance'
ERROR 2016-06-17 18:22:12,733 Internal Server Error: /options/readoutput/
Traceback (most recent call last):
  File "D:\python\python2.7.10\lib\site-packages\django\core\handlers\base.py", line 149, in get_response
    response = self.process_exception_by_middleware(e, request)
  File "D:\python\python2.7.10\lib\site-packages\django\core\handlers\base.py", line 147, in get_response
    response = wrapped_callback(request, *callback_args, **callback_kwargs)
  File "D:\python_dj\yunweiPT\options\views.py", line 19, in wrapper
    return func(request,*args,**kwargs)
  File "D:\python_dj\yunweiPT\options\views.py", line 137, in readoutput
    return HttpResponse(datainfo,context_instance=RequestContext(request))
  File "D:\python\python2.7.10\lib\site-packages\django\http\response.py", line 283, in __init__
    super(HttpResponse, self).__init__(*args, **kwargs)
TypeError: __init__() got an unexpected keyword argument 'context_instance'
ERROR 2016-06-17 18:26:09,270 Internal Server Error: /options/remoteoptions/
Traceback (most recent call last):
  File "D:\python\python2.7.10\lib\site-packages\django\core\handlers\base.py", line 149, in get_response
    response = self.process_exception_by_middleware(e, request)
  File "D:\python\python2.7.10\lib\site-packages\django\core\handlers\base.py", line 147, in get_response
    response = wrapped_callback(request, *callback_args, **callback_kwargs)
  File "D:\python_dj\yunweiPT\options\views.py", line 19, in wrapper
    return func(request,*args,**kwargs)
  File "D:\python_dj\yunweiPT\options\views.py", line 102, in remoteoptions
    return HttpResponse('OK',context_instance=RequestContext(request))
  File "D:\python\python2.7.10\lib\site-packages\django\http\response.py", line 283, in __init__
    super(HttpResponse, self).__init__(*args, **kwargs)
TypeError: __init__() got an unexpected keyword argument 'context_instance'
ERROR 2016-06-17 18:26:11,323 Internal Server Error: /options/readoutput/
Traceback (most recent call last):
  File "D:\python\python2.7.10\lib\site-packages\django\core\handlers\base.py", line 149, in get_response
    response = self.process_exception_by_middleware(e, request)
  File "D:\python\python2.7.10\lib\site-packages\django\core\handlers\base.py", line 147, in get_response
    response = wrapped_callback(request, *callback_args, **callback_kwargs)
  File "D:\python_dj\yunweiPT\options\views.py", line 19, in wrapper
    return func(request,*args,**kwargs)
  File "D:\python_dj\yunweiPT\options\views.py", line 137, in readoutput
    return HttpResponse(datainfo,context_instance=RequestContext(request))
  File "D:\python\python2.7.10\lib\site-packages\django\http\response.py", line 283, in __init__
    super(HttpResponse, self).__init__(*args, **kwargs)
TypeError: __init__() got an unexpected keyword argument 'context_instance'
ERROR 2016-06-17 18:26:13,345 Internal Server Error: /options/readoutput/
Traceback (most recent call last):
  File "D:\python\python2.7.10\lib\site-packages\django\core\handlers\base.py", line 149, in get_response
    response = self.process_exception_by_middleware(e, request)
  File "D:\python\python2.7.10\lib\site-packages\django\core\handlers\base.py", line 147, in get_response
    response = wrapped_callback(request, *callback_args, **callback_kwargs)
  File "D:\python_dj\yunweiPT\options\views.py", line 19, in wrapper
    return func(request,*args,**kwargs)
  File "D:\python_dj\yunweiPT\options\views.py", line 137, in readoutput
    return HttpResponse(datainfo,context_instance=RequestContext(request))
  File "D:\python\python2.7.10\lib\site-packages\django\http\response.py", line 283, in __init__
    super(HttpResponse, self).__init__(*args, **kwargs)
TypeError: __init__() got an unexpected keyword argument 'context_instance'
ERROR 2016-06-17 18:26:15,348 Internal Server Error: /options/readoutput/
Traceback (most recent call last):
  File "D:\python\python2.7.10\lib\site-packages\django\core\handlers\base.py", line 149, in get_response
    response = self.process_exception_by_middleware(e, request)
  File "D:\python\python2.7.10\lib\site-packages\django\core\handlers\base.py", line 147, in get_response
    response = wrapped_callback(request, *callback_args, **callback_kwargs)
  File "D:\python_dj\yunweiPT\options\views.py", line 19, in wrapper
    return func(request,*args,**kwargs)
  File "D:\python_dj\yunweiPT\options\views.py", line 137, in readoutput
    return HttpResponse(datainfo,context_instance=RequestContext(request))
  File "D:\python\python2.7.10\lib\site-packages\django\http\response.py", line 283, in __init__
    super(HttpResponse, self).__init__(*args, **kwargs)
TypeError: __init__() got an unexpected keyword argument 'context_instance'
ERROR 2016-06-17 18:26:17,341 Internal Server Error: /options/readoutput/
Traceback (most recent call last):
  File "D:\python\python2.7.10\lib\site-packages\django\core\handlers\base.py", line 149, in get_response
    response = self.process_exception_by_middleware(e, request)
  File "D:\python\python2.7.10\lib\site-packages\django\core\handlers\base.py", line 147, in get_response
    response = wrapped_callback(request, *callback_args, **callback_kwargs)
  File "D:\python_dj\yunweiPT\options\views.py", line 19, in wrapper
    return func(request,*args,**kwargs)
  File "D:\python_dj\yunweiPT\options\views.py", line 137, in readoutput
    return HttpResponse(datainfo,context_instance=RequestContext(request))
  File "D:\python\python2.7.10\lib\site-packages\django\http\response.py", line 283, in __init__
    super(HttpResponse, self).__init__(*args, **kwargs)
TypeError: __init__() got an unexpected keyword argument 'context_instance'
ERROR 2016-06-17 18:26:19,338 Internal Server Error: /options/readoutput/
Traceback (most recent call last):
  File "D:\python\python2.7.10\lib\site-packages\django\core\handlers\base.py", line 149, in get_response
    response = self.process_exception_by_middleware(e, request)
  File "D:\python\python2.7.10\lib\site-packages\django\core\handlers\base.py", line 147, in get_response
    response = wrapped_callback(request, *callback_args, **callback_kwargs)
  File "D:\python_dj\yunweiPT\options\views.py", line 19, in wrapper
    return func(request,*args,**kwargs)
  File "D:\python_dj\yunweiPT\options\views.py", line 137, in readoutput
    return HttpResponse(datainfo,context_instance=RequestContext(request))
  File "D:\python\python2.7.10\lib\site-packages\django\http\response.py", line 283, in __init__
    super(HttpResponse, self).__init__(*args, **kwargs)
TypeError: __init__() got an unexpected keyword argument 'context_instance'
ERROR 2016-06-17 18:26:21,341 Internal Server Error: /options/readoutput/
Traceback (most recent call last):
  File "D:\python\python2.7.10\lib\site-packages\django\core\handlers\base.py", line 149, in get_response
    response = self.process_exception_by_middleware(e, request)
  File "D:\python\python2.7.10\lib\site-packages\django\core\handlers\base.py", line 147, in get_response
    response = wrapped_callback(request, *callback_args, **callback_kwargs)
  File "D:\python_dj\yunweiPT\options\views.py", line 19, in wrapper
    return func(request,*args,**kwargs)
  File "D:\python_dj\yunweiPT\options\views.py", line 137, in readoutput
    return HttpResponse(datainfo,context_instance=RequestContext(request))
  File "D:\python\python2.7.10\lib\site-packages\django\http\response.py", line 283, in __init__
    super(HttpResponse, self).__init__(*args, **kwargs)
TypeError: __init__() got an unexpected keyword argument 'context_instance'
ERROR 2016-06-17 18:26:23,339 Internal Server Error: /options/readoutput/
Traceback (most recent call last):
  File "D:\python\python2.7.10\lib\site-packages\django\core\handlers\base.py", line 149, in get_response
    response = self.process_exception_by_middleware(e, request)
  File "D:\python\python2.7.10\lib\site-packages\django\core\handlers\base.py", line 147, in get_response
    response = wrapped_callback(request, *callback_args, **callback_kwargs)
  File "D:\python_dj\yunweiPT\options\views.py", line 19, in wrapper
    return func(request,*args,**kwargs)
  File "D:\python_dj\yunweiPT\options\views.py", line 137, in readoutput
    return HttpResponse(datainfo,context_instance=RequestContext(request))
  File "D:\python\python2.7.10\lib\site-packages\django\http\response.py", line 283, in __init__
    super(HttpResponse, self).__init__(*args, **kwargs)
TypeError: __init__() got an unexpected keyword argument 'context_instance'
ERROR 2016-06-17 18:26:25,342 Internal Server Error: /options/readoutput/
Traceback (most recent call last):
  File "D:\python\python2.7.10\lib\site-packages\django\core\handlers\base.py", line 149, in get_response
    response = self.process_exception_by_middleware(e, request)
  File "D:\python\python2.7.10\lib\site-packages\django\core\handlers\base.py", line 147, in get_response
    response = wrapped_callback(request, *callback_args, **callback_kwargs)
  File "D:\python_dj\yunweiPT\options\views.py", line 19, in wrapper
    return func(request,*args,**kwargs)
  File "D:\python_dj\yunweiPT\options\views.py", line 137, in readoutput
    return HttpResponse(datainfo,context_instance=RequestContext(request))
  File "D:\python\python2.7.10\lib\site-packages\django\http\response.py", line 283, in __init__
    super(HttpResponse, self).__init__(*args, **kwargs)
TypeError: __init__() got an unexpected keyword argument 'context_instance'
ERROR 2016-06-17 18:26:27,348 Internal Server Error: /options/readoutput/
Traceback (most recent call last):
  File "D:\python\python2.7.10\lib\site-packages\django\core\handlers\base.py", line 149, in get_response
    response = self.process_exception_by_middleware(e, request)
  File "D:\python\python2.7.10\lib\site-packages\django\core\handlers\base.py", line 147, in get_response
    response = wrapped_callback(request, *callback_args, **callback_kwargs)
  File "D:\python_dj\yunweiPT\options\views.py", line 19, in wrapper
    return func(request,*args,**kwargs)
  File "D:\python_dj\yunweiPT\options\views.py", line 137, in readoutput
    return HttpResponse(datainfo,context_instance=RequestContext(request))
  File "D:\python\python2.7.10\lib\site-packages\django\http\response.py", line 283, in __init__
    super(HttpResponse, self).__init__(*args, **kwargs)
TypeError: __init__() got an unexpected keyword argument 'context_instance'
ERROR 2016-06-17 18:26:29,338 Internal Server Error: /options/readoutput/
Traceback (most recent call last):
  File "D:\python\python2.7.10\lib\site-packages\django\core\handlers\base.py", line 149, in get_response
    response = self.process_exception_by_middleware(e, request)
  File "D:\python\python2.7.10\lib\site-packages\django\core\handlers\base.py", line 147, in get_response
    response = wrapped_callback(request, *callback_args, **callback_kwargs)
  File "D:\python_dj\yunweiPT\options\views.py", line 19, in wrapper
    return func(request,*args,**kwargs)
  File "D:\python_dj\yunweiPT\options\views.py", line 137, in readoutput
    return HttpResponse(datainfo,context_instance=RequestContext(request))
  File "D:\python\python2.7.10\lib\site-packages\django\http\response.py", line 283, in __init__
    super(HttpResponse, self).__init__(*args, **kwargs)
TypeError: __init__() got an unexpected keyword argument 'context_instance'
ERROR 2016-06-17 18:26:31,342 Internal Server Error: /options/readoutput/
Traceback (most recent call last):
  File "D:\python\python2.7.10\lib\site-packages\django\core\handlers\base.py", line 149, in get_response
    response = self.process_exception_by_middleware(e, request)
  File "D:\python\python2.7.10\lib\site-packages\django\core\handlers\base.py", line 147, in get_response
    response = wrapped_callback(request, *callback_args, **callback_kwargs)
  File "D:\python_dj\yunweiPT\options\views.py", line 19, in wrapper
    return func(request,*args,**kwargs)
  File "D:\python_dj\yunweiPT\options\views.py", line 137, in readoutput
    return HttpResponse(datainfo,context_instance=RequestContext(request))
  File "D:\python\python2.7.10\lib\site-packages\django\http\response.py", line 283, in __init__
    super(HttpResponse, self).__init__(*args, **kwargs)
TypeError: __init__() got an unexpected keyword argument 'context_instance'
ERROR 2016-06-17 18:26:33,336 Internal Server Error: /options/readoutput/
Traceback (most recent call last):
  File "D:\python\python2.7.10\lib\site-packages\django\core\handlers\base.py", line 149, in get_response
    response = self.process_exception_by_middleware(e, request)
  File "D:\python\python2.7.10\lib\site-packages\django\core\handlers\base.py", line 147, in get_response
    response = wrapped_callback(request, *callback_args, **callback_kwargs)
  File "D:\python_dj\yunweiPT\options\views.py", line 19, in wrapper
    return func(request,*args,**kwargs)
  File "D:\python_dj\yunweiPT\options\views.py", line 137, in readoutput
    return HttpResponse(datainfo,context_instance=RequestContext(request))
  File "D:\python\python2.7.10\lib\site-packages\django\http\response.py", line 283, in __init__
    super(HttpResponse, self).__init__(*args, **kwargs)
TypeError: __init__() got an unexpected keyword argument 'context_instance'
ERROR 2016-06-17 18:26:35,335 Internal Server Error: /options/readoutput/
Traceback (most recent call last):
  File "D:\python\python2.7.10\lib\site-packages\django\core\handlers\base.py", line 149, in get_response
    response = self.process_exception_by_middleware(e, request)
  File "D:\python\python2.7.10\lib\site-packages\django\core\handlers\base.py", line 147, in get_response
    response = wrapped_callback(request, *callback_args, **callback_kwargs)
  File "D:\python_dj\yunweiPT\options\views.py", line 19, in wrapper
    return func(request,*args,**kwargs)
  File "D:\python_dj\yunweiPT\options\views.py", line 137, in readoutput
    return HttpResponse(datainfo,context_instance=RequestContext(request))
  File "D:\python\python2.7.10\lib\site-packages\django\http\response.py", line 283, in __init__
    super(HttpResponse, self).__init__(*args, **kwargs)
TypeError: __init__() got an unexpected keyword argument 'context_instance'
ERROR 2016-06-17 18:26:37,351 Internal Server Error: /options/readoutput/
Traceback (most recent call last):
  File "D:\python\python2.7.10\lib\site-packages\django\core\handlers\base.py", line 149, in get_response
    response = self.process_exception_by_middleware(e, request)
  File "D:\python\python2.7.10\lib\site-packages\django\core\handlers\base.py", line 147, in get_response
    response = wrapped_callback(request, *callback_args, **callback_kwargs)
  File "D:\python_dj\yunweiPT\options\views.py", line 19, in wrapper
    return func(request,*args,**kwargs)
  File "D:\python_dj\yunweiPT\options\views.py", line 137, in readoutput
    return HttpResponse(datainfo,context_instance=RequestContext(request))
  File "D:\python\python2.7.10\lib\site-packages\django\http\response.py", line 283, in __init__
    super(HttpResponse, self).__init__(*args, **kwargs)
TypeError: __init__() got an unexpected keyword argument 'context_instance'
ERROR 2016-06-17 18:26:39,338 Internal Server Error: /options/readoutput/
Traceback (most recent call last):
  File "D:\python\python2.7.10\lib\site-packages\django\core\handlers\base.py", line 149, in get_response
    response = self.process_exception_by_middleware(e, request)
  File "D:\python\python2.7.10\lib\site-packages\django\core\handlers\base.py", line 147, in get_response
    response = wrapped_callback(request, *callback_args, **callback_kwargs)
  File "D:\python_dj\yunweiPT\options\views.py", line 19, in wrapper
    return func(request,*args,**kwargs)
  File "D:\python_dj\yunweiPT\options\views.py", line 137, in readoutput
    return HttpResponse(datainfo,context_instance=RequestContext(request))
  File "D:\python\python2.7.10\lib\site-packages\django\http\response.py", line 283, in __init__
    super(HttpResponse, self).__init__(*args, **kwargs)
TypeError: __init__() got an unexpected keyword argument 'context_instance'
ERROR 2016-06-17 18:26:41,341 Internal Server Error: /options/readoutput/
Traceback (most recent call last):
  File "D:\python\python2.7.10\lib\site-packages\django\core\handlers\base.py", line 149, in get_response
    response = self.process_exception_by_middleware(e, request)
  File "D:\python\python2.7.10\lib\site-packages\django\core\handlers\base.py", line 147, in get_response
    response = wrapped_callback(request, *callback_args, **callback_kwargs)
  File "D:\python_dj\yunweiPT\options\views.py", line 19, in wrapper
    return func(request,*args,**kwargs)
  File "D:\python_dj\yunweiPT\options\views.py", line 137, in readoutput
    return HttpResponse(datainfo,context_instance=RequestContext(request))
  File "D:\python\python2.7.10\lib\site-packages\django\http\response.py", line 283, in __init__
    super(HttpResponse, self).__init__(*args, **kwargs)
TypeError: __init__() got an unexpected keyword argument 'context_instance'
ERROR 2016-06-17 18:26:43,342 Internal Server Error: /options/readoutput/
Traceback (most recent call last):
  File "D:\python\python2.7.10\lib\site-packages\django\core\handlers\base.py", line 149, in get_response
    response = self.process_exception_by_middleware(e, request)
  File "D:\python\python2.7.10\lib\site-packages\django\core\handlers\base.py", line 147, in get_response
    response = wrapped_callback(request, *callback_args, **callback_kwargs)
  File "D:\python_dj\yunweiPT\options\views.py", line 19, in wrapper
    return func(request,*args,**kwargs)
  File "D:\python_dj\yunweiPT\options\views.py", line 137, in readoutput
    return HttpResponse(datainfo,context_instance=RequestContext(request))
  File "D:\python\python2.7.10\lib\site-packages\django\http\response.py", line 283, in __init__
    super(HttpResponse, self).__init__(*args, **kwargs)
TypeError: __init__() got an unexpected keyword argument 'context_instance'
ERROR 2016-06-17 18:26:45,322 Internal Server Error: /options/readoutput/
Traceback (most recent call last):
  File "D:\python\python2.7.10\lib\site-packages\django\core\handlers\base.py", line 149, in get_response
    response = self.process_exception_by_middleware(e, request)
  File "D:\python\python2.7.10\lib\site-packages\django\core\handlers\base.py", line 147, in get_response
    response = wrapped_callback(request, *callback_args, **callback_kwargs)
  File "D:\python_dj\yunweiPT\options\views.py", line 19, in wrapper
    return func(request,*args,**kwargs)
  File "D:\python_dj\yunweiPT\options\views.py", line 137, in readoutput
    return HttpResponse(datainfo,context_instance=RequestContext(request))
  File "D:\python\python2.7.10\lib\site-packages\django\http\response.py", line 283, in __init__
    super(HttpResponse, self).__init__(*args, **kwargs)
TypeError: __init__() got an unexpected keyword argument 'context_instance'
ERROR 2016-06-17 18:26:47,341 Internal Server Error: /options/readoutput/
Traceback (most recent call last):
  File "D:\python\python2.7.10\lib\site-packages\django\core\handlers\base.py", line 149, in get_response
    response = self.process_exception_by_middleware(e, request)
  File "D:\python\python2.7.10\lib\site-packages\django\core\handlers\base.py", line 147, in get_response
    response = wrapped_callback(request, *callback_args, **callback_kwargs)
  File "D:\python_dj\yunweiPT\options\views.py", line 19, in wrapper
    return func(request,*args,**kwargs)
  File "D:\python_dj\yunweiPT\options\views.py", line 137, in readoutput
    return HttpResponse(datainfo,context_instance=RequestContext(request))
  File "D:\python\python2.7.10\lib\site-packages\django\http\response.py", line 283, in __init__
    super(HttpResponse, self).__init__(*args, **kwargs)
TypeError: __init__() got an unexpected keyword argument 'context_instance'
ERROR 2016-06-17 18:26:49,342 Internal Server Error: /options/readoutput/
Traceback (most recent call last):
  File "D:\python\python2.7.10\lib\site-packages\django\core\handlers\base.py", line 149, in get_response
    response = self.process_exception_by_middleware(e, request)
  File "D:\python\python2.7.10\lib\site-packages\django\core\handlers\base.py", line 147, in get_response
    response = wrapped_callback(request, *callback_args, **callback_kwargs)
  File "D:\python_dj\yunweiPT\options\views.py", line 19, in wrapper
    return func(request,*args,**kwargs)
  File "D:\python_dj\yunweiPT\options\views.py", line 137, in readoutput
    return HttpResponse(datainfo,context_instance=RequestContext(request))
  File "D:\python\python2.7.10\lib\site-packages\django\http\response.py", line 283, in __init__
    super(HttpResponse, self).__init__(*args, **kwargs)
TypeError: __init__() got an unexpected keyword argument 'context_instance'
ERROR 2016-06-17 18:26:51,342 Internal Server Error: /options/readoutput/
Traceback (most recent call last):
  File "D:\python\python2.7.10\lib\site-packages\django\core\handlers\base.py", line 149, in get_response
    response = self.process_exception_by_middleware(e, request)
  File "D:\python\python2.7.10\lib\site-packages\django\core\handlers\base.py", line 147, in get_response
    response = wrapped_callback(request, *callback_args, **callback_kwargs)
  File "D:\python_dj\yunweiPT\options\views.py", line 19, in wrapper
    return func(request,*args,**kwargs)
  File "D:\python_dj\yunweiPT\options\views.py", line 137, in readoutput
    return HttpResponse(datainfo,context_instance=RequestContext(request))
  File "D:\python\python2.7.10\lib\site-packages\django\http\response.py", line 283, in __init__
    super(HttpResponse, self).__init__(*args, **kwargs)
TypeError: __init__() got an unexpected keyword argument 'context_instance'
ERROR 2016-06-17 18:26:53,336 Internal Server Error: /options/readoutput/
Traceback (most recent call last):
  File "D:\python\python2.7.10\lib\site-packages\django\core\handlers\base.py", line 149, in get_response
    response = self.process_exception_by_middleware(e, request)
  File "D:\python\python2.7.10\lib\site-packages\django\core\handlers\base.py", line 147, in get_response
    response = wrapped_callback(request, *callback_args, **callback_kwargs)
  File "D:\python_dj\yunweiPT\options\views.py", line 19, in wrapper
    return func(request,*args,**kwargs)
  File "D:\python_dj\yunweiPT\options\views.py", line 137, in readoutput
    return HttpResponse(datainfo,context_instance=RequestContext(request))
  File "D:\python\python2.7.10\lib\site-packages\django\http\response.py", line 283, in __init__
    super(HttpResponse, self).__init__(*args, **kwargs)
TypeError: __init__() got an unexpected keyword argument 'context_instance'
ERROR 2016-06-17 18:26:55,336 Internal Server Error: /options/readoutput/
Traceback (most recent call last):
  File "D:\python\python2.7.10\lib\site-packages\django\core\handlers\base.py", line 149, in get_response
    response = self.process_exception_by_middleware(e, request)
  File "D:\python\python2.7.10\lib\site-packages\django\core\handlers\base.py", line 147, in get_response
    response = wrapped_callback(request, *callback_args, **callback_kwargs)
  File "D:\python_dj\yunweiPT\options\views.py", line 19, in wrapper
    return func(request,*args,**kwargs)
  File "D:\python_dj\yunweiPT\options\views.py", line 137, in readoutput
    return HttpResponse(datainfo,context_instance=RequestContext(request))
  File "D:\python\python2.7.10\lib\site-packages\django\http\response.py", line 283, in __init__
    super(HttpResponse, self).__init__(*args, **kwargs)
TypeError: __init__() got an unexpected keyword argument 'context_instance'
ERROR 2016-06-17 18:26:57,335 Internal Server Error: /options/readoutput/
Traceback (most recent call last):
  File "D:\python\python2.7.10\lib\site-packages\django\core\handlers\base.py", line 149, in get_response
    response = self.process_exception_by_middleware(e, request)
  File "D:\python\python2.7.10\lib\site-packages\django\core\handlers\base.py", line 147, in get_response
    response = wrapped_callback(request, *callback_args, **callback_kwargs)
  File "D:\python_dj\yunweiPT\options\views.py", line 19, in wrapper
    return func(request,*args,**kwargs)
  File "D:\python_dj\yunweiPT\options\views.py", line 137, in readoutput
    return HttpResponse(datainfo,context_instance=RequestContext(request))
  File "D:\python\python2.7.10\lib\site-packages\django\http\response.py", line 283, in __init__
    super(HttpResponse, self).__init__(*args, **kwargs)
TypeError: __init__() got an unexpected keyword argument 'context_instance'
ERROR 2016-06-17 18:26:59,329 Internal Server Error: /options/readoutput/
Traceback (most recent call last):
  File "D:\python\python2.7.10\lib\site-packages\django\core\handlers\base.py", line 149, in get_response
    response = self.process_exception_by_middleware(e, request)
  File "D:\python\python2.7.10\lib\site-packages\django\core\handlers\base.py", line 147, in get_response
    response = wrapped_callback(request, *callback_args, **callback_kwargs)
  File "D:\python_dj\yunweiPT\options\views.py", line 19, in wrapper
    return func(request,*args,**kwargs)
  File "D:\python_dj\yunweiPT\options\views.py", line 137, in readoutput
    return HttpResponse(datainfo,context_instance=RequestContext(request))
  File "D:\python\python2.7.10\lib\site-packages\django\http\response.py", line 283, in __init__
    super(HttpResponse, self).__init__(*args, **kwargs)
TypeError: __init__() got an unexpected keyword argument 'context_instance'
ERROR 2016-06-17 18:27:01,345 Internal Server Error: /options/readoutput/
Traceback (most recent call last):
  File "D:\python\python2.7.10\lib\site-packages\django\core\handlers\base.py", line 149, in get_response
    response = self.process_exception_by_middleware(e, request)
  File "D:\python\python2.7.10\lib\site-packages\django\core\handlers\base.py", line 147, in get_response
    response = wrapped_callback(request, *callback_args, **callback_kwargs)
  File "D:\python_dj\yunweiPT\options\views.py", line 19, in wrapper
    return func(request,*args,**kwargs)
  File "D:\python_dj\yunweiPT\options\views.py", line 137, in readoutput
    return HttpResponse(datainfo,context_instance=RequestContext(request))
  File "D:\python\python2.7.10\lib\site-packages\django\http\response.py", line 283, in __init__
    super(HttpResponse, self).__init__(*args, **kwargs)
TypeError: __init__() got an unexpected keyword argument 'context_instance'
ERROR 2016-06-17 18:27:03,344 Internal Server Error: /options/readoutput/
Traceback (most recent call last):
  File "D:\python\python2.7.10\lib\site-packages\django\core\handlers\base.py", line 149, in get_response
    response = self.process_exception_by_middleware(e, request)
  File "D:\python\python2.7.10\lib\site-packages\django\core\handlers\base.py", line 147, in get_response
    response = wrapped_callback(request, *callback_args, **callback_kwargs)
  File "D:\python_dj\yunweiPT\options\views.py", line 19, in wrapper
    return func(request,*args,**kwargs)
  File "D:\python_dj\yunweiPT\options\views.py", line 137, in readoutput
    return HttpResponse(datainfo,context_instance=RequestContext(request))
  File "D:\python\python2.7.10\lib\site-packages\django\http\response.py", line 283, in __init__
    super(HttpResponse, self).__init__(*args, **kwargs)
TypeError: __init__() got an unexpected keyword argument 'context_instance'
ERROR 2016-06-20 09:32:27,476 Internal Server Error: /options/remoteoptions/
Traceback (most recent call last):
  File "D:\python\python2.7.10\lib\site-packages\django\core\handlers\base.py", line 149, in get_response
    response = self.process_exception_by_middleware(e, request)
  File "D:\python\python2.7.10\lib\site-packages\django\core\handlers\base.py", line 147, in get_response
    response = wrapped_callback(request, *callback_args, **callback_kwargs)
  File "D:\python_dj\yunweiPT\options\views.py", line 19, in wrapper
    return func(request,*args,**kwargs)
  File "D:\python_dj\yunweiPT\options\views.py", line 102, in remoteoptions
    return HttpResponse('OK',context_instance=RequestContext(request))
  File "D:\python\python2.7.10\lib\site-packages\django\http\response.py", line 283, in __init__
    super(HttpResponse, self).__init__(*args, **kwargs)
TypeError: __init__() got an unexpected keyword argument 'context_instance'
ERROR 2016-06-20 09:49:14,453 Internal Server Error: /options/remoteoptions/
Traceback (most recent call last):
  File "D:\python\python2.7.10\lib\site-packages\django\core\handlers\base.py", line 149, in get_response
    response = self.process_exception_by_middleware(e, request)
  File "D:\python\python2.7.10\lib\site-packages\django\core\handlers\base.py", line 147, in get_response
    response = wrapped_callback(request, *callback_args, **callback_kwargs)
  File "D:\python_dj\yunweiPT\options\views.py", line 20, in wrapper
    return func(request,*args,**kwargs)
  File "D:\python\python2.7.10\lib\site-packages\django\views\decorators\csrf.py", line 58, in wrapped_view
    return view_func(*args, **kwargs)
  File "D:\python_dj\yunweiPT\options\views.py", line 104, in remoteoptions
    return HttpResponse('OK',context_instance=RequestContext(request))
  File "D:\python\python2.7.10\lib\site-packages\django\http\response.py", line 283, in __init__
    super(HttpResponse, self).__init__(*args, **kwargs)
TypeError: __init__() got an unexpected keyword argument 'context_instance'
ERROR 2016-06-20 09:51:35,210 Internal Server Error: /options/remoteoptions/
Traceback (most recent call last):
  File "D:\python\python2.7.10\lib\site-packages\django\core\handlers\base.py", line 149, in get_response
    response = self.process_exception_by_middleware(e, request)
  File "D:\python\python2.7.10\lib\site-packages\django\core\handlers\base.py", line 147, in get_response
    response = wrapped_callback(request, *callback_args, **callback_kwargs)
  File "D:\python\python2.7.10\lib\site-packages\django\views\decorators\csrf.py", line 58, in wrapped_view
    return view_func(*args, **kwargs)
  File "D:\python_dj\yunweiPT\options\views.py", line 20, in wrapper
    return func(request,*args,**kwargs)
  File "D:\python_dj\yunweiPT\options\views.py", line 104, in remoteoptions
    return HttpResponse('OK',context_instance=RequestContext(request))
  File "D:\python\python2.7.10\lib\site-packages\django\http\response.py", line 283, in __init__
    super(HttpResponse, self).__init__(*args, **kwargs)
TypeError: __init__() got an unexpected keyword argument 'context_instance'
ERROR 2016-06-20 09:51:37,270 Internal Server Error: /options/readoutput/
Traceback (most recent call last):
  File "D:\python\python2.7.10\lib\site-packages\django\core\handlers\base.py", line 149, in get_response
    response = self.process_exception_by_middleware(e, request)
  File "D:\python\python2.7.10\lib\site-packages\django\core\handlers\base.py", line 147, in get_response
    response = wrapped_callback(request, *callback_args, **callback_kwargs)
  File "D:\python\python2.7.10\lib\site-packages\django\views\decorators\csrf.py", line 58, in wrapped_view
    return view_func(*args, **kwargs)
  File "D:\python_dj\yunweiPT\options\views.py", line 20, in wrapper
    return func(request,*args,**kwargs)
  File "D:\python_dj\yunweiPT\options\views.py", line 140, in readoutput
    return HttpResponse(datainfo,context_instance=RequestContext(request))
  File "D:\python\python2.7.10\lib\site-packages\django\http\response.py", line 283, in __init__
    super(HttpResponse, self).__init__(*args, **kwargs)
TypeError: __init__() got an unexpected keyword argument 'context_instance'
ERROR 2016-06-20 09:51:39,290 Internal Server Error: /options/readoutput/
Traceback (most recent call last):
  File "D:\python\python2.7.10\lib\site-packages\django\core\handlers\base.py", line 149, in get_response
    response = self.process_exception_by_middleware(e, request)
  File "D:\python\python2.7.10\lib\site-packages\django\core\handlers\base.py", line 147, in get_response
    response = wrapped_callback(request, *callback_args, **callback_kwargs)
  File "D:\python\python2.7.10\lib\site-packages\django\views\decorators\csrf.py", line 58, in wrapped_view
    return view_func(*args, **kwargs)
  File "D:\python_dj\yunweiPT\options\views.py", line 20, in wrapper
    return func(request,*args,**kwargs)
  File "D:\python_dj\yunweiPT\options\views.py", line 140, in readoutput
    return HttpResponse(datainfo,context_instance=RequestContext(request))
  File "D:\python\python2.7.10\lib\site-packages\django\http\response.py", line 283, in __init__
    super(HttpResponse, self).__init__(*args, **kwargs)
TypeError: __init__() got an unexpected keyword argument 'context_instance'
ERROR 2016-06-20 09:51:41,289 Internal Server Error: /options/readoutput/
Traceback (most recent call last):
  File "D:\python\python2.7.10\lib\site-packages\django\core\handlers\base.py", line 149, in get_response
    response = self.process_exception_by_middleware(e, request)
  File "D:\python\python2.7.10\lib\site-packages\django\core\handlers\base.py", line 147, in get_response
    response = wrapped_callback(request, *callback_args, **callback_kwargs)
  File "D:\python\python2.7.10\lib\site-packages\django\views\decorators\csrf.py", line 58, in wrapped_view
    return view_func(*args, **kwargs)
  File "D:\python_dj\yunweiPT\options\views.py", line 20, in wrapper
    return func(request,*args,**kwargs)
  File "D:\python_dj\yunweiPT\options\views.py", line 140, in readoutput
    return HttpResponse(datainfo,context_instance=RequestContext(request))
  File "D:\python\python2.7.10\lib\site-packages\django\http\response.py", line 283, in __init__
    super(HttpResponse, self).__init__(*args, **kwargs)
TypeError: __init__() got an unexpected keyword argument 'context_instance'
ERROR 2016-06-20 09:51:43,289 Internal Server Error: /options/readoutput/
Traceback (most recent call last):
  File "D:\python\python2.7.10\lib\site-packages\django\core\handlers\base.py", line 149, in get_response
    response = self.process_exception_by_middleware(e, request)
  File "D:\python\python2.7.10\lib\site-packages\django\core\handlers\base.py", line 147, in get_response
    response = wrapped_callback(request, *callback_args, **callback_kwargs)
  File "D:\python\python2.7.10\lib\site-packages\django\views\decorators\csrf.py", line 58, in wrapped_view
    return view_func(*args, **kwargs)
  File "D:\python_dj\yunweiPT\options\views.py", line 20, in wrapper
    return func(request,*args,**kwargs)
  File "D:\python_dj\yunweiPT\options\views.py", line 140, in readoutput
    return HttpResponse(datainfo,context_instance=RequestContext(request))
  File "D:\python\python2.7.10\lib\site-packages\django\http\response.py", line 283, in __init__
    super(HttpResponse, self).__init__(*args, **kwargs)
TypeError: __init__() got an unexpected keyword argument 'context_instance'
ERROR 2016-06-20 09:51:45,279 Internal Server Error: /options/readoutput/
Traceback (most recent call last):
  File "D:\python\python2.7.10\lib\site-packages\django\core\handlers\base.py", line 149, in get_response
    response = self.process_exception_by_middleware(e, request)
  File "D:\python\python2.7.10\lib\site-packages\django\core\handlers\base.py", line 147, in get_response
    response = wrapped_callback(request, *callback_args, **callback_kwargs)
  File "D:\python\python2.7.10\lib\site-packages\django\views\decorators\csrf.py", line 58, in wrapped_view
    return view_func(*args, **kwargs)
  File "D:\python_dj\yunweiPT\options\views.py", line 20, in wrapper
    return func(request,*args,**kwargs)
  File "D:\python_dj\yunweiPT\options\views.py", line 140, in readoutput
    return HttpResponse(datainfo,context_instance=RequestContext(request))
  File "D:\python\python2.7.10\lib\site-packages\django\http\response.py", line 283, in __init__
    super(HttpResponse, self).__init__(*args, **kwargs)
TypeError: __init__() got an unexpected keyword argument 'context_instance'
ERROR 2016-06-20 09:51:47,290 Internal Server Error: /options/readoutput/
Traceback (most recent call last):
  File "D:\python\python2.7.10\lib\site-packages\django\core\handlers\base.py", line 149, in get_response
    response = self.process_exception_by_middleware(e, request)
  File "D:\python\python2.7.10\lib\site-packages\django\core\handlers\base.py", line 147, in get_response
    response = wrapped_callback(request, *callback_args, **callback_kwargs)
  File "D:\python\python2.7.10\lib\site-packages\django\views\decorators\csrf.py", line 58, in wrapped_view
    return view_func(*args, **kwargs)
  File "D:\python_dj\yunweiPT\options\views.py", line 20, in wrapper
    return func(request,*args,**kwargs)
  File "D:\python_dj\yunweiPT\options\views.py", line 140, in readoutput
    return HttpResponse(datainfo,context_instance=RequestContext(request))
  File "D:\python\python2.7.10\lib\site-packages\django\http\response.py", line 283, in __init__
    super(HttpResponse, self).__init__(*args, **kwargs)
TypeError: __init__() got an unexpected keyword argument 'context_instance'
ERROR 2016-06-20 09:51:49,296 Internal Server Error: /options/readoutput/
Traceback (most recent call last):
  File "D:\python\python2.7.10\lib\site-packages\django\core\handlers\base.py", line 149, in get_response
    response = self.process_exception_by_middleware(e, request)
  File "D:\python\python2.7.10\lib\site-packages\django\core\handlers\base.py", line 147, in get_response
    response = wrapped_callback(request, *callback_args, **callback_kwargs)
  File "D:\python\python2.7.10\lib\site-packages\django\views\decorators\csrf.py", line 58, in wrapped_view
    return view_func(*args, **kwargs)
  File "D:\python_dj\yunweiPT\options\views.py", line 20, in wrapper
    return func(request,*args,**kwargs)
  File "D:\python_dj\yunweiPT\options\views.py", line 140, in readoutput
    return HttpResponse(datainfo,context_instance=RequestContext(request))
  File "D:\python\python2.7.10\lib\site-packages\django\http\response.py", line 283, in __init__
    super(HttpResponse, self).__init__(*args, **kwargs)
TypeError: __init__() got an unexpected keyword argument 'context_instance'
ERROR 2016-06-20 09:51:51,269 Internal Server Error: /options/readoutput/
Traceback (most recent call last):
  File "D:\python\python2.7.10\lib\site-packages\django\core\handlers\base.py", line 149, in get_response
    response = self.process_exception_by_middleware(e, request)
  File "D:\python\python2.7.10\lib\site-packages\django\core\handlers\base.py", line 147, in get_response
    response = wrapped_callback(request, *callback_args, **callback_kwargs)
  File "D:\python\python2.7.10\lib\site-packages\django\views\decorators\csrf.py", line 58, in wrapped_view
    return view_func(*args, **kwargs)
  File "D:\python_dj\yunweiPT\options\views.py", line 20, in wrapper
    return func(request,*args,**kwargs)
  File "D:\python_dj\yunweiPT\options\views.py", line 140, in readoutput
    return HttpResponse(datainfo,context_instance=RequestContext(request))
  File "D:\python\python2.7.10\lib\site-packages\django\http\response.py", line 283, in __init__
    super(HttpResponse, self).__init__(*args, **kwargs)
TypeError: __init__() got an unexpected keyword argument 'context_instance'
ERROR 2016-06-20 09:51:53,292 Internal Server Error: /options/readoutput/
Traceback (most recent call last):
  File "D:\python\python2.7.10\lib\site-packages\django\core\handlers\base.py", line 149, in get_response
    response = self.process_exception_by_middleware(e, request)
  File "D:\python\python2.7.10\lib\site-packages\django\core\handlers\base.py", line 147, in get_response
    response = wrapped_callback(request, *callback_args, **callback_kwargs)
  File "D:\python\python2.7.10\lib\site-packages\django\views\decorators\csrf.py", line 58, in wrapped_view
    return view_func(*args, **kwargs)
  File "D:\python_dj\yunweiPT\options\views.py", line 20, in wrapper
    return func(request,*args,**kwargs)
  File "D:\python_dj\yunweiPT\options\views.py", line 140, in readoutput
    return HttpResponse(datainfo,context_instance=RequestContext(request))
  File "D:\python\python2.7.10\lib\site-packages\django\http\response.py", line 283, in __init__
    super(HttpResponse, self).__init__(*args, **kwargs)
TypeError: __init__() got an unexpected keyword argument 'context_instance'
ERROR 2016-06-20 09:52:24,653 Internal Server Error: /options/remoteoptions/
Traceback (most recent call last):
  File "D:\python\python2.7.10\lib\site-packages\django\core\handlers\base.py", line 149, in get_response
    response = self.process_exception_by_middleware(e, request)
  File "D:\python\python2.7.10\lib\site-packages\django\core\handlers\base.py", line 147, in get_response
    response = wrapped_callback(request, *callback_args, **callback_kwargs)
  File "D:\python_dj\yunweiPT\options\views.py", line 20, in wrapper
    return func(request,*args,**kwargs)
  File "D:\python_dj\yunweiPT\options\views.py", line 104, in remoteoptions
    return HttpResponse('OK',context_instance=RequestContext(request))
  File "D:\python\python2.7.10\lib\site-packages\django\http\response.py", line 283, in __init__
    super(HttpResponse, self).__init__(*args, **kwargs)
TypeError: __init__() got an unexpected keyword argument 'context_instance'
ERROR 2016-06-20 09:54:32,997 Internal Server Error: /options/remoteoptions/
Traceback (most recent call last):
  File "D:\python\python2.7.10\lib\site-packages\django\core\handlers\base.py", line 149, in get_response
    response = self.process_exception_by_middleware(e, request)
  File "D:\python\python2.7.10\lib\site-packages\django\core\handlers\base.py", line 147, in get_response
    response = wrapped_callback(request, *callback_args, **callback_kwargs)
  File "D:\python\python2.7.10\lib\site-packages\django\utils\decorators.py", line 149, in _wrapped_view
    response = view_func(request, *args, **kwargs)
  File "D:\python_dj\yunweiPT\options\views.py", line 20, in wrapper
    return func(request,*args,**kwargs)
  File "D:\python_dj\yunweiPT\options\views.py", line 104, in remoteoptions
    return HttpResponse('OK',context_instance=RequestContext(request))
  File "D:\python\python2.7.10\lib\site-packages\django\http\response.py", line 283, in __init__
    super(HttpResponse, self).__init__(*args, **kwargs)
TypeError: __init__() got an unexpected keyword argument 'context_instance'
ERROR 2016-06-20 09:54:58,907 Internal Server Error: /options/remoteoptions/
Traceback (most recent call last):
  File "D:\python\python2.7.10\lib\site-packages\django\core\handlers\base.py", line 149, in get_response
    response = self.process_exception_by_middleware(e, request)
  File "D:\python\python2.7.10\lib\site-packages\django\core\handlers\base.py", line 147, in get_response
    response = wrapped_callback(request, *callback_args, **callback_kwargs)
  File "D:\python_dj\yunweiPT\options\views.py", line 20, in wrapper
    return func(request,*args,**kwargs)
  File "D:\python\python2.7.10\lib\site-packages\django\utils\decorators.py", line 149, in _wrapped_view
    response = view_func(request, *args, **kwargs)
  File "D:\python_dj\yunweiPT\options\views.py", line 105, in remoteoptions
    return HttpResponse('OK',context_instance=RequestContext(request))
  File "D:\python\python2.7.10\lib\site-packages\django\http\response.py", line 283, in __init__
    super(HttpResponse, self).__init__(*args, **kwargs)
TypeError: __init__() got an unexpected keyword argument 'context_instance'
ERROR 2016-06-20 10:00:24,595 Internal Server Error: /options/remoteoptions/
Traceback (most recent call last):
  File "D:\python\python2.7.10\lib\site-packages\django\core\handlers\base.py", line 149, in get_response
    response = self.process_exception_by_middleware(e, request)
  File "D:\python\python2.7.10\lib\site-packages\django\core\handlers\base.py", line 147, in get_response
    response = wrapped_callback(request, *callback_args, **callback_kwargs)
  File "D:\python_dj\yunweiPT\options\views.py", line 20, in wrapper
    return func(request,*args,**kwargs)
  File "D:\python\python2.7.10\lib\site-packages\django\views\decorators\csrf.py", line 58, in wrapped_view
    return view_func(*args, **kwargs)
  File "D:\python_dj\yunweiPT\options\views.py", line 105, in remoteoptions
    return HttpResponse('OK',context_instance=RequestContext(request))
  File "D:\python\python2.7.10\lib\site-packages\django\http\response.py", line 283, in __init__
    super(HttpResponse, self).__init__(*args, **kwargs)
TypeError: __init__() got an unexpected keyword argument 'context_instance'
ERROR 2016-06-20 10:03:01,043 Internal Server Error: /options/remoteoptions/
Traceback (most recent call last):
  File "D:\python\python2.7.10\lib\site-packages\django\core\handlers\base.py", line 149, in get_response
    response = self.process_exception_by_middleware(e, request)
  File "D:\python\python2.7.10\lib\site-packages\django\core\handlers\base.py", line 147, in get_response
    response = wrapped_callback(request, *callback_args, **callback_kwargs)
  File "D:\python_dj\yunweiPT\options\views.py", line 20, in wrapper
    return func(request,*args,**kwargs)
  File "D:\python\python2.7.10\lib\site-packages\django\views\decorators\csrf.py", line 58, in wrapped_view
    return view_func(*args, **kwargs)
  File "D:\python_dj\yunweiPT\options\views.py", line 105, in remoteoptions
    return HttpResponse('OK',context_instance=RequestContext(request))
  File "D:\python\python2.7.10\lib\site-packages\django\http\response.py", line 283, in __init__
    super(HttpResponse, self).__init__(*args, **kwargs)
TypeError: __init__() got an unexpected keyword argument 'context_instance'
